Workbook

Sheet Report
C1: MPC PARAMETER SHEET - REPORT
B3: MANUFACTURER NAME
B5: MODEL
B7: DEVICE TYPE
B9: TEST SPECIFICATION
B10: EEBus_UC_HighLevel_TestSpecification_MPC_V1.0.2
B11: SCENARIO(S)
B12: e.g. 1, 2, 3, 4, 5
B13: NAME OF TESTER(S)
B16: Overall Status | D16: MA | E16: MU | F16: Total
B17: Number of ATCs | D17: {=SUMPRODUCT(--(ISNUMBER(SEARCH("ATC_MPC_",'Specific Test Cases'!B130:B257)) * ISNUMBER(SEARCH("MA",'Specific Test Cases'!B130:B257)) > 0))} -> 34 | E17: {=SUMPRODUCT(--(ISNUMBER(SEARCH("ATC_MPC_",'Specific Test Cases'!B60:B129)) * ISNUMBER(SEARCH("MU",'Specific Test Cases'!B60:B129)) > 0))} -> 20 | F17: {=SUMPRODUCT(--ISNUMBER(SEARCH("ATC_MPC_",'Specific Test Cases'!B60:B257)))} -> 54
B18: Number of STCs | D18: {=SUMPRODUCT(--ISNUMBER(VALUE('Specific Test Cases'!B130:B257)))} -> 94 | E18: {=SUMPRODUCT(--ISNUMBER(VALUE('Specific Test Cases'!B60:B129)))} -> 50 | F18: {=SUMPRODUCT(--ISNUMBER(VALUE('Specific Test Cases'!B60:B257)))} -> 144
B19: Test cycle duration | D19: =IF(COUNT('Specific Test Cases'!C57:C257)=0, "0 days", IF(MAX('Specific Test Cases'!C57:C257)=MIN('Specific Test Cases'!C57:C257), "1 day", TEXT(MAX('Specific Test Cases'!C57:C257)-MIN('Specific Test Cases'!C57:C257),"0") & " days")) -> 0 days
B21: Execution Status | D21: MA | E21: MU | F21: Total
B22: Number of STCs executed | D22: {=SUMPRODUCT((('Specific Test Cases'!K130:K257="Passed")+('Specific Test Cases'!K130:K257="Failed")+('Specific Test Cases'!K130:K257="Not applicable"))*1)} -> 0 | E22: {=SUMPRODUCT((('Specific Test Cases'!K60:K129="Passed")+('Specific Test Cases'!K60:K129="Failed")+('Specific Test Cases'!K60:K129="Not applicable"))*1)} -> 0 | F22: {=SUMPRODUCT((('Specific Test Cases'!K60:K257="Passed")+('Specific Test Cases'!K60:K257="Failed")+('Specific Test Cases'!K60:K257="Not applicable"))*1)} -> 0
C23: Number of passed STCs | D23: =COUNTIF('Specific Test Cases'!K130:K257,"Passed") -> 0 | E23: =COUNTIF('Specific Test Cases'!K60:K129,"Passed") -> 0 | F23: =COUNTIF('Specific Test Cases'!K60:K257,"Passed") -> 0
C24: Passed percentage | D24: =IF(OR(D23=0,D22=0),0,D23/D22) -> 0 | E24: =IF(OR(E23=0,E22=0),0,E23/E22) -> 0 | F24: =IF(OR(F23=0,F22=0),0,F23/F22) -> 0
C25: Number of failed STCs | D25: =COUNTIF('Specific Test Cases'!K130:K257,"Failed") -> 0 | E25: =COUNTIF('Specific Test Cases'!K60:K129,"Failed") -> 0 | F25: =COUNTIF('Specific Test Cases'!K60:K257,"Failed") -> 0
C26: Failed percentage | D26: =IF(OR(D25=0,D22=0),0,D25/D22) -> 0 | E26: =IF(OR(E25=0,E22=0),0,E25/E22) -> 0 | F26: =IF(OR(F25=0,F22=0),0,F25/F22) -> 0
C27: Number of not applicable STCs | D27: =COUNTIF('Specific Test Cases'!K130:K257,"Not applicable") -> 0 | E27: =COUNTIF('Specific Test Cases'!K60:K129,"Not applicable") -> 0 | F27: =COUNTIF('Specific Test Cases'!K60:K257,"Not applicable") -> 0
C28: Not applicable percentage | D28: =IF(OR(D27=0,D22=0),0,D27/D22) -> 0 | E28: =IF(OR(E27=0,E22=0),0,E27/E22) -> 0 | F28: =IF(OR(F27=0,F22=0),0,F27/F22) -> 0

Sheet Specific Test Cases
D1: MPC PARAMETER SHEET - TEST CASES
B3: TECHNOLOGY | D3: SPINE
B4: Actor
B6: DATA TRANSMISSION
D7: Usage | E7: Interval [seconds]
B8: Polling
B9: Notification
B11: CONNECTED PHASES
B12: Phase A
B13: Phase B
B14: Phase C
B16: SUPPORTED DATA POINTS
B17: Total Active Power
B18: Phase-Specific Active Power
B19: Total Consumed Energy
B20: Total Produced Energy
B21: Phase-Specific AC Current
... B23: AC Frequency
D25: ENERGY DIRECTION | E25: RANGES OF THE DUT
B26: TOTAL ACTIVE POWER [Watt] | E26: MIN | F26: MAX
B27: Power total | D27: consume
D28: produce
B29: PHASE-SPECIFIC ACTIVE POWER [Watt] | E29: MIN | F29: MAX
B30: Phase A | D30: consume
D31: produce
B32: Phase B | D32: consume
D33: produce
B34: Phase C | D34: consume
D35: produce
B36: TOTAL CONSUMED ENERGY [Watt-hour] | E36: MIN | F36: MAX
B37: Total consumed energy | D37: consume
D38: produce | E38: =IF(E41="","",E41) | F38: =IF(F41="","",F41)
B39: TOTAL PRODUCED ENERGY [Watt-hour] | E39: MIN | F39: MAX
B40: Total produced energy | D40: consume | E40: =IF(E37="","",E37) | F40: =IF(F37="","",F37)
D41: produce
B42: PHASE-SPECIFIC AC CURRENT [Ampere] | E42: MIN | F42: MAX
B43: Phase A | D43: consume
D44: produce
B45: Phase B | D45: consume
D46: produce
...

Sheet Comments
B1: MPC PARAMETER SHEET - COMMENTS
B3: TEST NO. | C3: TEST DATE | D3: GENERAL QUESTIONS / COMMENTS

Sheet Legend
B1: MPC PARAMETER SHEET - LEGEND
B3: Revisions
B4: Version | D4: Date/Editor
B5: V1.0.0 | D5: 2024-04-30 - SH
B6: V1.0.1 | D6: 2025-11-27 - SH & MW
B7: V1.0.2 | D7: 2026-07-17 - AS
B9: Specific Test Cases
D10: Cells with a white background need to be manually filled in with device specific information or information taken from the test specification.
D11: Greyed-out cells are filled in automatically.
B12: Data transmission | D12: Use the drop-down menu to select whether the DUT uses polling or notification. [YES/NO]
B13: Supported data points | D13: Use the drop-down menu to select which data point is supported by the DUT. [YES/NO]
B14: Data point values | D14: The corresponding data point values shall be filled in as follows: MU as DUT: The value received by the tester. (Optional: Compare the read value with the MU display.) MA as DUT: The received value of the MA. (Mandatory: Compare the read value with the tester display.)
B15: any | D15: Don't care
B16: Formatting rules
C17: Test verdict | D17: According to the chosen test verdict its background is colorized. [PASSED/FAILED/NOT APPLICABLE]
D18: Passed
D19: Failed
D20: Not applicable
