Workbook

Sheet Report
C1: LPP PARAMETER SHEET - REPORT
B3: MANUFACTURER NAME
B5: MODEL
B7: DEVICE TYPE
B9: TEST SPECIFICATION
B10: EEBus_UC_HighLevel_TestSpecification_LPP_V1.0.2
B11: SCENARIO(S)
B12: e.g. 1, 2, 3, 4
B13: NAME OF TESTER(S)
B16: Overall Status | D16: CS | E16: EG | F16: Total
B17: Number of ATCs | D17: {=SUMPRODUCT(--(ISNUMBER(SEARCH("ATC_LPP_",'Specific Test Cases'!B44:B193)) * ISNUMBER(SEARCH("CS",'Specific Test Cases'!B44:B193)) > 0))} -> 43 | E17: {=SUMPRODUCT(--(ISNUMBER(SEARCH("ATC_LPP_",'Specific Test Cases'!B44:B193)) * ISNUMBER(SEARCH("EG",'Specific Test Cases'!B44:B193)) > 0))} -> 8 | F17: {=SUMPRODUCT(--ISNUMBER(SEARCH("ATC_LPP_",'Specific Test Cases'!B44:B193)))} -> 51
B18: Number of STCs | D18: {=SUMPRODUCT(--ISNUMBER(VALUE('Specific Test Cases'!B68:B193)))} -> 84 | E18: {=SUMPRODUCT(--ISNUMBER(VALUE('Specific Test Cases'!B44:B66)))} -> 15 | F18: {=SUMPRODUCT(--ISNUMBER(VALUE('Specific Test Cases'!B44:B193)))} -> 99
B19: Test cycle duration | D19: =IF(COUNT('Specific Test Cases'!C44:C193)=0, "0 days", IF(MAX('Specific Test Cases'!C44:C193)=MIN('Specific Test Cases'!C44:C193), "1 day", TEXT(MAX('Specific Test Cases'!C44:C193)-MIN('Specific Test Cases'!C44:C193),"0") & " days")) -> 0 days
B21: Execution Status | D21: CS | E21: EG | F21: Total
B22: Number of STCs executed | D22: {=SUMPRODUCT((('Specific Test Cases'!S68:S193="Passed")+('Specific Test Cases'!S68:S193="Failed")+('Specific Test Cases'!S68:S193="Not applicable"))*1)} -> 0 | E22: {=SUMPRODUCT((('Specific Test Cases'!S45:S66="Passed")+('Specific Test Cases'!S45:S66="Failed")+('Specific Test Cases'!S45:S66="Not applicable"))*1)} -> 0 | F22: {=SUMPRODUCT((('Specific Test Cases'!S44:S193="Passed")+('Specific Test Cases'!S44:S193="Failed")+('Specific Test Cases'!S44:S193="Not applicable"))*1)} -> 0
C23: Number of passed STCs | D23: =COUNTIF('Specific Test Cases'!S68:S193,"Passed") -> 0 | E23: =COUNTIF('Specific Test Cases'!S45:S66,"Passed") -> 0 | F23: =COUNTIF('Specific Test Cases'!S44:S193,"Passed") -> 0
C24: Passed percentage | D24: =IF(OR(D23=0,D22=0),0,D23/D22) -> 0 | E24: =IF(OR(E23=0,E22=0),0,E23/E22) -> 0 | F24: =IF(OR(F23=0,F22=0),0,F23/F22) -> 0
C25: Number of failed STCs | D25: =COUNTIF('Specific Test Cases'!S68:S193,"Failed") -> 0 | E25: =COUNTIF('Specific Test Cases'!S45:S66,"Failed") -> 0 | F25: =COUNTIF('Specific Test Cases'!S44:S193,"Failed") -> 0
C26: Failed percentage | D26: =IF(OR(D25=0,D22=0),0,D25/D22) -> 0 | E26: =IF(OR(E25=0,E22=0),0,E25/E22) -> 0 | F26: =IF(OR(F25=0,F22=0),0,F25/F22) -> 0
C27: Number of not applicable STCs | D27: =COUNTIF('Specific Test Cases'!S68:S193,"Not applicable") -> 0 | E27: =COUNTIF('Specific Test Cases'!S45:S66,"Not applicable") -> 0 | F27: =COUNTIF('Specific Test Cases'!S44:S193,"Not applicable") -> 0
C28: Not applicable percentage | D28: =IF(OR(D27=0,D22=0),0,D27/D22) -> 0 | E28: =IF(OR(E27=0,E22=0),0,E27/E22) -> 0 | F28: =IF(OR(F27=0,F22=0),0,F27/F22) -> 0

Sheet Specific Test Cases
D1: LPP PARAMETER SHEET - TEST CASES
B3: TECHNOLOGY | D3: e.g. SPINE
B4: Actor
B5: CS type CEM?
B7: STARTUP DURATION [seconds]
B8: StartUpDur_EG
B9: StartUpDur_CS
B11: ACTIVE POWER PRODUCTION LIMIT [Watt] | F11: CONSTRAINTS
B12: APPLmin | D12: -0.1 | F12: APPL_min < APPL_max ≤ 0
B13: APPLmax | D13: 0 | F13: APPL_min < APPL_max ≤ 0
C14: delta | D14: =0.05*(D13-D12) -> 0.005
B15: APPL_01 | D15: =IF((D13+D14)<0,D13+D14,0) -> 0 | F15: APPL_05 < APPL_04 < APPL_03 < APPL_02 < APPL_01 ≤ 0
B16: APPL_02 | D16: =D13-D14 -> -0.005 | F16: APPL_05 < APPL_04 < APPL_03 < APPL_02 < APPL_01 ≤ 0
B17: APPL_03 | F17: APPL_05 < APPL_04 < APPL_03 < APPL_02 < APPL_01 ≤ 0
B18: APPL_04 | D18: =D12+D14 -> -0.095 | F18: APPL_05 < APPL_04 < APPL_03 < APPL_02 < APPL_01 ≤ 0
B19: APPL_05 | D19: =D12-D14 -> -0.105 | F19: APPL_05 < APPL_04 < APPL_03 < APPL_02 < APPL_01 ≤ 0
B20: APPL_06 | D20: 1000
B21: FAILSAFE PRODUCTION ACTIVE POWER LIMIT [Watt] | F21: CONSTRAINTS
B22: PFPAPL | F22: 0 ≤ PFPAPL
B23: FPAPLmin | D23: 0 | F23: 0 ≤ FPAPL_min < FPAPL_max
B24: FPAPLmax | D24: 0.1 | F24: 0 ≤ FPAPL_min < FPAPL_max
C25: delta | D25: =0.05*(D24-D23) -> 0.005
B26: FPAPL_01 | D26: =IF((D23-D25)>0,D23-D25,0) -> 0 | F26: 0 ≤ FPAPL_01 < FPAPL_02 < FPAPL_03 < FPAPL_04 < FPAPL_05
B27: FPAPL_02 | D27: =D23+D25 -> 0.005 | F27: 0 ≤ FPAPL_01 < FPAPL_02 < FPAPL_03 < FPAPL_04 < FPAPL_05
B28: FPAPL_03 | F28: 0 ≤ FPAPL_01 < FPAPL_02 < FPAPL_03 < FPAPL_04 < FPAPL_05
B29: FPAPL_04 | D29: =D24-D25 -> 0.095 | F29: 0 ≤ FPAPL_01 < FPAPL_02 < FPAPL_03 < FPAPL_04 < FPAPL_05
B30: FPAPL_05 | D30: =D24+D25 -> 0.105 | F30: 0 ≤ FPAPL_01 < FPAPL_02 < FPAPL_03 < FPAPL_04 < FPAPL_05
B31: FPAPL_06 | D31: -1000
B32: FAILSAFE DURATION MINIMUM [h[m[s]]] | F32: CONSTRAINTS
B33: MFSDM | F33: 2h ≤ PFSDM ≤ MFSDM
B34: PFSDM | F34: 2h ≤ PFSDM ≤ MFSDM
B35: FPAPL_DUR_01 | D35: 6840
B36: FPAPL_DUR_02 | F36: PFSDM < FPAPL_DUR_02 < MFSDM OR FPAPL_DUR_02 = MFSDM (*) | I36: (*) applies only if PFSDM ≥ MFSDM
B37: FPAPL_DUR_03 | D37: =1.05*D33 -> 0 | F37: 1.05 * MFSDM
B38: POWER PRODUCTION NOMINAL MAX [Watt] | F38: CONSTRAINTS
B39: Value | F39: 0 < Power Production Nominal Max
B40: CONTRACTUAL PRODUCTION NOMINAL MAX [Watt] | F40: CONSTRAINTS
B41: Value | F41: 0 < Contractual Production Nominal Max
B43: STC ID | C43: TEST DATE | D43: APPL USED IN TEST STEP | E43: ACTIVE POWER PRODUCTION LIMIT - APPL [Watt] | G43: MESSAGE COMBINATIONS | H43: ACTIVE POWER PRODUCTION LIMIT DURATION [seconds] | J43: FPAPL USED IN TEST STEP | K43: FAILSAFE PRODUCTION ACTIVE POWER LIMIT - FPAPL [Watt] | M43: FAILSAFE DURATION MINIMUM USED IN TEST STEP | N43: FAILSAFE DURATION MINIMUM [h[m[s]]] | P43: POWER PRODUCTION NOMINAL MAX [Watt] | Q43: CONTRACTUAL PRODUCTION NOMINAL MAX [Watt] | R43: STARTUP DURATION [seconds] | S43: TEST VERDICT | T43: COMMENTS / NOTES / ADDITIONS
B44: ATC_LPP_COM_PT_EGHeartbeat_001
...

Sheet Optional Support
D1: LPP PARAMETER SHEET - OPTIONAL SUPPORT
B3: Manufacturer statements on the support of optional protocol functionality.
B4: NO. | C4: SUPPORTED? [Yes/No] | D4: ACTOR | E4: FUNCTIONALITY | F4: SCENARIO | G4: MANDATORY ATC TO VERIFY STATEMENT | H4: COMMENTS
B5: A1 | D5: Energy Guard | E5: read/write APPL (value, activation flag, duration) | F5: 1 | G5: ATC_LPP_COM_PT_EGMessages_003
B6: A2 | D6: Energy Guard | E6: read/write FPAPL and Failsafe Duration Minimum | F6: 2 | G6: ATC_LPP_COM_PT_EGMessages_004
B7: A3 | D7: Energy Guard | E7: read Power Production Nominal Max | F7: 4 | G7: -
B8: A4 | D8: Energy Guard | E8: read Contractual Production Nominal Max | F8: 4 | G8: -
B9: A5 | D9: Energy Guard | E9: quick resend write APPL if previous write APPL was rejected | F9: 1 | G9: ATC_LPP_COM_PT_EGMessages_002
B10: A6 | D10: Energy Guard | E10: ongoing adjustment of CS' limit parameters | F10: 1, 2 | G10: ATC_LPP_COM_PT_EGMessages_003, ATC_LPP_COM_PT_EGMessages_004
B12: B1 | D12: Controllable System at "LPP instance 1" | E12: report Contractual Production Nominal Max | F12: 4 | G12: ATC_LPP_COM_PT_CSUnlCntrl_002 | H12: Note: only works in conjunction with B2
B13: B2 | D13: Controllable System at "LPP instance 1" | E13: no report of Power Production Nominal Max | F13: 4 | G13: ATC_LPP_COM_PT_CSUnlCntrl_002 | H13: Note: only works in conjunction with B1
B14: B3 | D14: Controllable System at "LPP instance 1" | E14: permitted rejection of received APPL write command | F14: 1 | G14: ATC_LPP_INS1_PT_CSTransition1_001
B16: C1 | D16: Controllable System at "LPP instance 2" | E16: report Power Production Nominal Max | F16: 4 | G16: ATC_LPP_COM_PT_CSUnlCntrl_003 | H16: Note: only works in conjunction with C2
B17: C2 | D17: Controllable System at "LPP instance 2" | E17: no report Contractual Production Nominal Max | F17: 4 | G17: ATC_LPP_COM_PT_CSUnlCntrl_003 | H17: Note: only works in conjunction with C1
B18: C3 | D18: Controllable System at "LPP instance 2" | E18: permitted rejection of received APPL write command | F18: 1 | G18: ATC_LPP_INS2_PT_CSTransition1_001
B20: D1 | D20: Controllable System at any LPP instance | E20: auto-adjust too large received APPL | F20: 1 | G20: ATC_LPP_COM_PT_CSConnection_006
B21: D2 | D21: Controllable System at any LPP instance | E21: state "unlimited/autonomous" implemented | F21: 1, 2, 3 | G21: ATC_LPP_COM_NT_CSUnlAuto_001, ATC_LPP_COM_PT_CSTransition3_001, ATC_LPP_COM_PT_CSTransition3_002, ATC_LPP_COM_PT_CSTransition10_001, ATC_LPP_COM_PT_CSTransition10_002, ATC_LPP_COM_PT_CSTransition11_001, ATC_LPP_COM_PT_CSTransition11_002, ATC_LPP_COM_PT_CSTransition12_001
B22: D3 | D22: Controllable System at any LPP instance | E22: store FPAPL and Failsafe Duration Minimum values persistently | F22: - | G22: ATC_LPP_COM_PT_CSInit_003
B24: E1 | D24: Energy Guard | E24: black start | F24: - | G24: ATC_LPP_COM_PT_EGConnection_003
B25: E2 | D25: Controllable System at any LPP instance | E25: black start | F25: - | G25: ATC_LPP_COM_PT_CSConnection_009
B27: Supplementary optional verifications
B28: NO. | C28: VERIFY? [Yes/No] | D28: ACTOR | E28: FUNCTIONALITY | F28: SCENARIO | G28: MANDATORY ATC TO VERIFY STATEMENT | H28: COMMENTS
B29: M1 | D29: Controllable System at "LPP instance 1" | E29: limit production according to Contractual Production Nominal Max | F29: 4 | G29: ATC_LPP_COM_PT_CSUnlAuto_002 | H29: Note: only works in conjunction with N1 and requires B1
B31: N1 | D31: Controllable System at "LPP instance 2" | E31: limit production according to Power Production Nominal Max | F31: 4 | G31: ATC_LPP_COM_PT_CSUnlAuto_002 | H31: Note: only works in conjunction with M1 and requires C1
B33: Legend
B34: read "X" | D34: Get value of "X" of the other actor.
B35: write "X" | D35: Set new/changed value of "X" of the other actor or delete "X".
B36: report "X" | D36: The actor owning "X" sends the value of "X" to the other actor.

Sheet Comments
B1: LPP PARAMETER SHEET - COMMENTS
B3: TEST NO. | C3: TEST DATE | D3: GENERAL QUESTIONS / COMMENTS

Sheet Legend
B1: LPP PARAMETER SHEET - LEGEND
B3: Revisions
B4: Version | D4: Date/Editor
B5: V1.0.0 | D5: 2024-04-30 - SH
B6: V1.0.1 | D6: 2025-11-27 - SH & MW
B7: V1.0.2 | D7: 2026-07-17 - MW & AS
B9: Specific Test Cases
D10: Cells with a white background need to be manually filled in with device specific information or information taken from the test specification.
D11: Greyed-out cells are filled in automatically.
B12: Formatting rules
D13: The cell background in which the values for APPLmax and FPAPLmax are entered turns red for visual support when entering wrong values or values in a wrong range. In addition, the cell of the calculated delta is coloured red in this case.
C14: Test verdict | D14: According to the chosen test verdict its background is colorized. [PASSED/FAILED/NOT APPLICABLE]
D15: Passed
D16: Failed
D17: Not applicable
B19: Optional Support
B20: Supported/Verify? [Yes/No] | D20: Use the drop-down menu to select whether the corresponding ATCs are also to be tested. These ATCs are then to be tested with defined data as STCs. [YES/NO]
